<?xml version='1.0'?>

<robot name="my_robot" xmlns:xacro="http://www.ros.org/wiki/xacro">
  
  <xacro:include filename="$(find my_robot)/urdf/my_robot.gazebo"/>

  <link name="robot_footprint"></link>

  <joint name="robot_footprint_joint" type="fixed">
    <origin xyz="0 0 0" rpy="0 0 0"/>
    <parent link="robot_footprint"/>
    <child link="chassis"/>
  </joint>

  <link name='chassis'>
    <origin xyz="0 0 0" rpy="0 0 0"/>

    <inertial>
      <mass value="20.0"/>
      <origin xyz="0 0 0" rpy="0 0 0"/>
      <inertia ixx="0.1" ixy="0" ixz="0"
               iyy="0.1" iyz="0"
               izz="0.1"
      />
    </inertial>

    <collision name='chassis_collision'>
      <origin xyz="0 0 0" rpy=" 0 0 0"/> 
      <geometry>
        <box size=".6 .3 .1"/>
      </geometry>
    </collision>

    <visual name='chassis_visual'>
      <origin xyz="0 0 0" rpy=" 0 0 0"/>
      <geometry>
        <box size=".6 .3 .15"/>
      </geometry>
    </visual>

    <collision name='hokuyo_base_collision'>
      <origin xyz="0 0 0.12" rpy=" 0 0 0"/> 
      <geometry>
        <cylinder length="0.1" radius="0.05"/>
      </geometry>
    </collision>

    <visual name='hokuyo_base_visual'>
      <origin xyz="0 0 0.12" rpy=" 0 0 0"/>
      <geometry>
        <cylinder length="0.1" radius="0.05"/>
      </geometry>
    </visual>
  </link>

  <joint type="continuous" name="front_left_wheel_hinge">
    <origin xyz="0.25 0.2 0" rpy="0 0 0"/>
    <child link="front_left_wheel"/>
    <parent link="chassis"/>
    <axis xyz="0 1 0" rpy="0 0 0"/>
    <limit effort="10000" velocity="1000"/>
    <dynamics damping="1.0" friction="1.0"/>
  </joint>

  <link name="front_left_wheel">
    <origin xyz="0 0 0" rpy="0 0 0"/>

    <inertial>
      <mass value="5.0"/>
      <inertia ixx="0.1" ixy="0" ixz="0"
               iyy="0.1" iyz="0"
               izz="0.1"/>
    </inertial>

    <collision name='front_left_wheel_collision'>
      <origin xyz="0 0 0" rpy=" 0 1.5707 1.5707"/> 
      <geometry>
        <cylinder length="0.05" radius="0.1"/>
      </geometry>
    </collision>

    <visual name='front_left_wheel_visual'>
      <origin xyz="0 0 0" rpy=" 0 1.5707 1.5707"/> 
      <geometry>
        <cylinder length="0.05" radius="0.1"/>
      </geometry>
    </visual>

  </link>

  <joint type="continuous" name="front_right_wheel_hinge">
    <origin xyz="0.25 -0.2 0" rpy="0 0 0"/>
    <child link="front_right_wheel"/>
    <parent link="chassis"/>
    <axis xyz="0 1 0" rpy="0 0 0"/>
    <limit effort="10000" velocity="1000"/>
    <dynamics damping="1.0" friction="1.0"/>
  </joint>

  <link name="front_right_wheel">

    <origin xyz="0 0 0" rpy="0 0 0"/>

    <inertial>
      <mass value="5.0"/>
      <inertia ixx="0.1" ixy="0" ixz="0"
               iyy="0.1" iyz="0"
               izz="0.1"/>
    </inertial>

    <collision name='front_right_wheel_collision'>
      <origin xyz="0 0 0" rpy=" 0 1.5707 1.5707"/> 
      <geometry>
        <cylinder length="0.05" radius="0.1"/>
      </geometry>
    </collision>

    <visual name='front_right_wheel_visual'>
      <origin xyz="0 0 0" rpy=" 0 1.5707 1.5707"/> 
      <geometry>
        <cylinder length="0.05" radius="0.1"/>
      </geometry>
    </visual>

  </link>

  <joint type="continuous" name="back_left_wheel_hinge">
    <origin xyz="-0.25 0.2 0" rpy="0 0 0"/>
    <child link="back_left_wheel"/>
    <parent link="chassis"/>
    <axis xyz="0 1 0" rpy="0 0 0"/>
    <limit effort="10000" velocity="1000"/>
    <dynamics damping="1.0" friction="1.0"/>
  </joint>

  <link name="back_left_wheel">
    <origin xyz="0 0 0" rpy="0 0 0"/>

    <inertial>
      <mass value="5.0"/>
      <inertia ixx="0.1" ixy="0" ixz="0"
               iyy="0.1" iyz="0"
               izz="0.1"/>
    </inertial>

    <collision name='back_left_wheel_collision'>
      <origin xyz="0 0 0" rpy=" 0 1.5707 1.5707"/> 
      <geometry>
        <cylinder length="0.05" radius="0.1"/>
      </geometry>
    </collision>

    <visual name='back_left_wheel_visual'>
      <origin xyz="0 0 0" rpy=" 0 1.5707 1.5707"/> 
      <geometry>
        <cylinder length="0.05" radius="0.1"/>
      </geometry>
    </visual>

  </link>

  <joint type="continuous" name="back_right_wheel_hinge">
    <origin xyz="-0.25 -0.2 0" rpy="0 0 0"/>
    <child link="back_right_wheel"/>
    <parent link="chassis"/>
    <axis xyz="0 1 0" rpy="0 0 0"/>
    <limit effort="10000" velocity="1000"/>
    <dynamics damping="1.0" friction="1.0"/>
  </joint>

  <link name="back_right_wheel">

    <origin xyz="0 0 0" rpy="0 0 0"/>

    <inertial>
      <mass value="5.0"/>
      <inertia ixx="0.1" ixy="0" ixz="0"
               iyy="0.1" iyz="0"
               izz="0.1"/>
    </inertial>

    <collision name='back_right_wheel_collision'>
      <origin xyz="0 0 0" rpy=" 0 1.5707 1.5707"/> 
      <geometry>
        <cylinder length="0.05" radius="0.1"/>
      </geometry>
    </collision>

    <visual name='back_right_wheel_visual'>
      <origin xyz="0 0 0" rpy=" 0 1.5707 1.5707"/> 
      <geometry>
        <cylinder length="0.05" radius="0.1"/>
      </geometry>
    </visual>

  </link>

  <joint type="fixed" name="camera_joint">
    <origin xyz="0.3 0 0.04" rpy="0 0 0"/>
    <child link="camera"/>
    <parent link="chassis"/>
    <axis xyz="0 1 0" rpy="0 0 0"/>
  </joint>

  <link name="camera">

    <origin xyz="0 0 0" rpy="0 0 0"/>

    <inertial>
      <mass value="0.1"/>
      <inertia ixx="1e-6" ixy="0" ixz="0"
               iyy="1e-6" iyz="0"
               izz="1e-6"/>
    </inertial>

    <collision name='camera_collision'>
      <origin xyz="0 0 0" rpy=" 0 0 0"/> 
      <geometry>
        <box size="0.05 0.05 0.05"/>
      </geometry>
    </collision>

    <visual name='camera_visual'>
      <origin xyz="0 0 0" rpy=" 0 0 0"/> 
      <geometry>
        <box size="0.05 0.05 0.05"/>
      </geometry>
    </visual>

  </link>

  <joint type="fixed" name="hokuyo_joint">
    <origin xyz="0 0 0.2" rpy="0 0 0"/>
    <child link="hokuyo"/>
    <parent link="chassis"/>
    <axis xyz="0 1 0" rpy="0 0 0"/>
  </joint>

  <link name="hokuyo">
    <origin xyz="0 0 0" rpy="0 0 0"/>

    <inertial>
      <mass value="1e-5"/>
      <inertia ixx="1e-6" ixy="0" ixz="0"
               iyy="1e-6" iyz="0"
               izz="1e-6"/>
    </inertial>

    <collision name='hokuyo_collision'>
      <origin xyz="0 0 0" rpy=" 0 0 0"/> 
      <geometry>
        <box size="0.1 0.1 0.1"/>
      </geometry>
    </collision>

    <visual name='hokuyo_visual'>
      <origin xyz="0 0 0" rpy=" 0 0 0"/> 
      <geometry>
        <mesh filename="package://my_robot/meshes/hokuyo.dae"/>
      </geometry>
    </visual>

  </link>

<gazebo reference="front_left_wheel">
    <material>Gazebo/Black</material>
</gazebo>

<gazebo reference="front_right_wheel">
    <material>Gazebo/Black</material>
</gazebo>

<gazebo reference="back_left_wheel">
    <material>Gazebo/Black</material>
</gazebo>

<gazebo reference="back_right_wheel">
    <material>Gazebo/Black</material>
</gazebo>

<gazebo reference="chassis">
    <material>Gazebo/Purple</material>
</gazebo>

<gazebo reference="camera">
    <material>Gazebo/Green</material>
</gazebo>

</robot>